Workbook

Sheet Monthly Pay
A1: Employee Name | B1: Designation | C1: Monthly Pay
A2: Rupali | C2: 30000
A3: Parimal | C3: 30000
A4: Dipansu | C4: 15000
A5: Hassan | C5: 10000
A6: Himanshu | C6: 8500
A7: Biswajeet | C7: 45000
A8: Sumit | C8: 45000
A9: Shruti | C9: 25000
A10: Laxman | C10: 15000
A11: Faizan | C11: 8500
A12: Siddhi | C12: 0
A13: aayushman | C13: 8500
... A16: Gulab | C16: 35000

Sheet Project List
A1: Company | B1: Project Name | D1: Project Lead | E1: Testers | F1: monthly pay of testers | G1: Project Income | H1: Start Date | I1: End Date | J1: Status
A2: CSS | B2: Encora | C2: Web/cloud | D2: Rupali | E2: Rupali | F2: =_xlfn.XLOOKUP(E2,'Monthly Pay'!A:A,'Monthly Pay'!C:C) -> 30000 | G2: 200000 | H2: 46054 | I2: 46185 | J2: web Completed, cloud , network, red teaming is pending
B3: Encora | C3: Network | E3: Parimal | F3: =_xlfn.XLOOKUP(E3,'Monthly Pay'!A:A,'Monthly Pay'!C:C) -> 30000 | H3: 46054 | I3: 46203 | J3: Revalidation
B4: Encora | E4: Dipansu | F4: =_xlfn.XLOOKUP(E4,'Monthly Pay'!A:A,'Monthly Pay'!C:C) -> 15000
B5: Encora | E5: Hassan | F5: =_xlfn.XLOOKUP(E5,'Monthly Pay'!A:A,'Monthly Pay'!C:C) -> 10000
B6: Encora | E6: Himanshu | F6: =_xlfn.XLOOKUP(E6,'Monthly Pay'!A:A,'Monthly Pay'!C:C) -> 8500
A7: Mitkat | B7: RXIL | C7: Fintech, ITFS | D7: Biswajeet | E7: Biswajeet | F7: =_xlfn.XLOOKUP(E7,'Monthly Pay'!A:A,'Monthly Pay'!C:C) -> 45000
B8: RXIL | E8: Shruti | F8: =_xlfn.XLOOKUP(E8,'Monthly Pay'!A:A,'Monthly Pay'!C:C) -> 25000
B9: RXIL | E9: Laxman | F9: =_xlfn.XLOOKUP(E9,'Monthly Pay'!A:A,'Monthly Pay'!C:C) -> 15000
B10: RXIL | E10: Faizan | F10: =_xlfn.XLOOKUP(E10,'Monthly Pay'!A:A,'Monthly Pay'!C:C) -> 8500
B11: RXIL | E11: Siddhi
A12: Mitkat | B12: Lumina | D12: Biswajeet | E12: Biswajeet | F12: =_xlfn.XLOOKUP(E12,'Monthly Pay'!A:A,'Monthly Pay'!C:C) -> 45000 | H12: 45931
B13: Lumina | E13: Sanchit | F13: =_xlfn.XLOOKUP(E13,'Monthly Pay'!A:A,'Monthly Pay'!C:C) -> 30000
B14: Lumina | E14: Parimal | F14: =_xlfn.XLOOKUP(E14,'Monthly Pay'!A:A,'Monthly Pay'!C:C) -> 30000
B15: Lumina
B16: Lumina
A17: Mitkat | B17: LVP | D17: Biswajeet | E17: Biswajeet | F17: =_xlfn.XLOOKUP(E17,'Monthly Pay'!A:A,'Monthly Pay'!C:C) -> 45000 | H17: 46174
B18: LVP | E18: Parimal | F18: =_xlfn.XLOOKUP(E18,'Monthly Pay'!A:A,'Monthly Pay'!C:C) -> 30000
B19: LVP
B20: LVP
B21: LVP
A22: CSS | B22: Advantage go | D22: Rupali | E22: Rupali | F22: =_xlfn.XLOOKUP(E22,'Monthly Pay'!A:A,'Monthly Pay'!C:C) -> 30000 | H22: 46149 | I22: 46175 | J22: revalidation on hold by sarvesh sir
B23: Advantage go
B24: Advantage go
B25: Advantage go
B26: Advantage go
A27: CSS | B27: UNO Ai | D27: Rupali | E27: Rupali | F27: =_xlfn.XLOOKUP(E27,'Monthly Pay'!A:A,'Monthly Pay'!C:C) -> 30000 | H27: 46149 | I27: 46170 | J27: Revalidation
B28: UNO Ai | E28: Dipansu | F28: =_xlfn.XLOOKUP(E28,'Monthly Pay'!A:A,'Monthly Pay'!C:C) -> 15000
B29: UNO Ai | E29: Hassan | F29: =_xlfn.XLOOKUP(E29,'Monthly Pay'!A:A,'Monthly Pay'!C:C) -> 10000
B30: UNO Ai | E30: Gulab | F30: =_xlfn.XLOOKUP(E30,'Monthly Pay'!A:A,'Monthly Pay'!C:C) -> 35000
B31: UNO Ai
A32: CSS | B32: Decklar | C32: honeycomb, radar, hive,API | D32: Parimal | E32: Parimal | F32: =_xlfn.XLOOKUP(E32,'Monthly Pay'!A:A,'Monthly Pay'!C:C) -> 30000 | H32: 46160 | J32: revalidation
B33: Decklar | E33: Laxman | F33: =_xlfn.XLOOKUP(E33,'Monthly Pay'!A:A,'Monthly Pay'!C:C) -> 15000
B34: Decklar | E34: Gulab | F34: =_xlfn.XLOOKUP(E34,'Monthly Pay'!A:A,'Monthly Pay'!C:C) -> 35000
B35: Decklar | E35: Himanshu | F35: =_xlfn.XLOOKUP(E35,'Monthly Pay'!A:A,'Monthly Pay'!C:C) -> 8500
A36: Mitkat | B36: Mehery | D36: Biswajeet | E36: Biswajeet | F36: =_xlfn.XLOOKUP(E36,'Monthly Pay'!A:A,'Monthly Pay'!C:C) -> 45000 | H36: 46174 | J36: Blackbox testing
B37: Mehery | E37: Gulab | F37: =_xlfn.XLOOKUP(E37,'Monthly Pay'!A:A,'Monthly Pay'!C:C) -> 35000
B38: Mehery | E38: Shruti | F38: =_xlfn.XLOOKUP(E38,'Monthly Pay'!A:A,'Monthly Pay'!C:C) -> 25000
B39: Mehery | E39: Laxman | F39: =_xlfn.XLOOKUP(E39,'Monthly Pay'!A:A,'Monthly Pay'!C:C) -> 15000
B40: Mehery
...

Sheet Mitkat
A1: Project Name | B1: Project Lead | C1: Status
A2: RXIL | B2: Biswajeet ray | C2: CKYC source code revalidation has been completed Udyem bharat source code KSEB source code report is under preparation ITFS application completed Fintech is pending from client
A3: LVP | B3: Biswajeet ray | C3: Router audit is done Web application done Server ip done Pending:- Access point, firewall
A4: Lumina | B4: Biswajeet ray | C4: Pending:- Ip range Switches and routers Ids/ips Access point in progress Firewall in progress
A5: Mehery | B5: Biswajeet ray | C5: Push app is done smart conversation is pending from client side Blackbox in progress Greybox pending from client side
A6: Hashconnect | B6: Biswajeet ray | C6: Revalidation not fixed from client side
A7: Avanse | B7: Biswajeet ray | C7: Paused waiting for inderjeet
A8: Decklar | B8: Parimal | C8: Revalidation
A9: Venture | B9: Parimal | C9: Revalidation

Sheet Summary
A1: Project Name | B1: Company | C1: Testers | D1: monthly pay of testers | E1: Income (₹) | F1: Gross Profit (₹) | G1: Margin % | H1: Status | J1: Project Name | K1: monthly pay of testers | L1: Income (₹) | M1: Gross Profit (₹)
A2: Encora | B2: CSS | C2: {=_xlfn.TEXTJOIN(",",TRUE,IF(('Project List'!B:B=Summary!A2)*('Project List'!E:E<>""),'Project List'!E:E,""))} -> Rupali,Parimal,Dipansu,Hassan,Himanshu | D2: =SUMIF('Project List'!B:B,A2,'Project List'!F:F) -> 93500 | F2: =E2-D2 -> -93500 | J2: Encora | K2: =_xlfn.XLOOKUP($J$2,$A:$A,D:D) -> 93500 | L2: =_xlfn.XLOOKUP($J$2,$A:$A,E:E) -> 0 | M2: =_xlfn.XLOOKUP($J$2,$A:$A,F:F) -> -93500
A3: ='Project List'!B7 -> RXIL | B3: Mitkat | C3: {=_xlfn.TEXTJOIN(",",TRUE,IF(('Project List'!B:B=Summary!A3)*('Project List'!E:E<>""),'Project List'!E:E,""))} -> Biswajeet,Shruti,Laxman,Faizan,Siddhi | D3: =SUMIF('Project List'!B:B,A3,'Project List'!F:F) -> 93500
A4: ='Project List'!B12 -> Lumina | B4: Mitkat | C4: {=_xlfn.TEXTJOIN(",",TRUE,IF(('Project List'!B:B=Summary!A4)*('Project List'!E:E<>""),'Project List'!E:E,""))} -> Biswajeet,Sanchit,Parimal | D4: =SUMIF('Project List'!B:B,A4,'Project List'!F:F) -> 105000
A5: ='Project List'!B17 -> LVP | B5: Mitkat | C5: {=_xlfn.TEXTJOIN(",",TRUE,IF(('Project List'!B:B=Summary!A5)*('Project List'!E:E<>""),'Project List'!E:E,""))} -> Biswajeet,Parimal | D5: =SUMIF('Project List'!B:B,A5,'Project List'!F:F) -> 75000
A6: ='Project List'!B22 -> Advantage go | B6: CSS | C6: {=_xlfn.TEXTJOIN(",",TRUE,IF(('Project List'!B:B=Summary!A6)*('Project List'!E:E<>""),'Project List'!E:E,""))} -> Rupali | D6: =SUMIF('Project List'!B:B,A6,'Project List'!F:F) -> 30000
A7: ='Project List'!B27 -> UNO Ai | B7: CSS | C7: {=_xlfn.TEXTJOIN(",",TRUE,IF(('Project List'!B:B=Summary!A7)*('Project List'!E:E<>""),'Project List'!E:E,""))} -> Rupali,Dipansu,Hassan,Gulab | D7: =SUMIF('Project List'!B:B,A7,'Project List'!F:F) -> 90000
A8: ='Project List'!B32 -> Decklar | B8: CSS | C8: {=_xlfn.TEXTJOIN(",",TRUE,IF(('Project List'!B:B=Summary!A8)*('Project List'!E:E<>""),'Project List'!E:E,""))} -> Parimal,Laxman,Gulab,Himanshu | D8: =SUMIF('Project List'!B:B,A8,'Project List'!F:F) -> 88500
A9: ='Project List'!B36 -> Mehery | B9: Mitkat | C9: {=_xlfn.TEXTJOIN(",",TRUE,IF(('Project List'!B:B=Summary!A9)*('Project List'!E:E<>""),'Project List'!E:E,""))} -> Biswajeet,Gulab,Shruti,Laxman | D9: =SUMIF('Project List'!B:B,A9,'Project List'!F:F) -> 120000
A10: ='Project List'!B41 -> Annadarpan phase 2 | B10: CSS | C10: {=_xlfn.TEXTJOIN(",",TRUE,IF(('Project List'!B:B=Summary!A10)*('Project List'!E:E<>""),'Project List'!E:E,""))} -> Rupali | D10: =SUMIF('Project List'!B:B,A10,'Project List'!F:F) -> 30000
A11: ='Project List'!B46 -> Arjas Steel | B11: CSS | C11: {=_xlfn.TEXTJOIN(",",TRUE,IF(('Project List'!B:B=Summary!A11)*('Project List'!E:E<>""),'Project List'!E:E,""))} -> Sumit,Aayushman | D11: =SUMIF('Project List'!B:B,A11,'Project List'!F:F) -> 53500
A12: ='Project List'!B51 -> ASG | B12: CSS | C12: {=_xlfn.TEXTJOIN(",",TRUE,IF(('Project List'!B:B=Summary!A12)*('Project List'!E:E<>""),'Project List'!E:E,""))} -> Sumit,Swarup | D12: =SUMIF('Project List'!B:B,A12,'Project List'!F:F) -> 60000
A13: ='Project List'!B56 -> Jio Blackrock | B13: Mitkat | C13: {=_xlfn.TEXTJOIN(",",TRUE,IF(('Project List'!B:B=Summary!A13)*('Project List'!E:E<>""),'Project List'!E:E,""))} -> Parimal | D13: =SUMIF('Project List'!B:B,A13,'Project List'!F:F) -> 30000
A14: ='Project List'!B61 -> Paraviste | B14: Mitkat | C14: {=_xlfn.TEXTJOIN(",",TRUE,IF(('Project List'!B:B=Summary!A14)*('Project List'!E:E<>""),'Project List'!E:E,""))} -> Parimal | D14: =SUMIF('Project List'!B:B,A14,'Project List'!F:F) -> 30000
A15: ='Project List'!B66 -> Arjas SAP VAPT | B15: CSS | C15: {=_xlfn.TEXTJOIN(",",TRUE,IF(('Project List'!B:B=Summary!A15)*('Project List'!E:E<>""),'Project List'!E:E,""))} -> Sanchit,Sumit | D15: =SUMIF('Project List'!B:B,A15,'Project List'!F:F) -> 75000
A16: Venture | B16: Mitkat | C16: {=_xlfn.TEXTJOIN(",",TRUE,IF(('Project List'!B:B=Summary!A16)*('Project List'!E:E<>""),'Project List'!E:E,""))} -> Parimal | D16: =SUMIF('Project List'!B:B,A16,'Project List'!F:F) -> 30000
